<?xml version="1.0" ?>
<!-- =================================================================================== -->
<!-- |    This document was autogenerated by xacro from /home/benzi/benzi_ws/src/redundancy_solver/robots/xacro/mmo_500.urdf.xacro | -->
<!-- |    EDITING THIS FILE BY HAND IS NOT RECOMMENDED                                 | -->
<!-- =================================================================================== -->
<!-- Materials -->
<robot name="mmo_500" xmlns:xacro="http://www.ros.org/wiki/xacro">
    <gazebo reference="base_link">
        <gravity>true</gravity>
        <self_collide>false</self_collide>
    </gazebo>
    <gazebo reference="mpo_500_omni_wheel_front_left_link">
        <gravity>true</gravity>
        <self_collide>false</self_collide>
    </gazebo>
    <gazebo reference="mpo_500_omni_wheel_front_right_link">
        <gravity>true</gravity>
        <self_collide>false</self_collide>
    </gazebo>
    <gazebo reference="mpo_500_omni_wheel_back_left_link">
        <gravity>true</gravity>
        <self_collide>false</self_collide>
    </gazebo>
    <gazebo reference="mpo_500_omni_wheel_back_right_link">
        <gravity>true</gravity>
        <self_collide>false</self_collide>
    </gazebo>
    <!-- Lidar sensors -->
    <gazebo reference="lidar_1_link">
        <sensor name="lidar_1_sensor" type="ray">
            <pose>0 0 0 0 0 0</pose>
            <visualize>false</visualize>
            <update_rate>40</update_rate>
            <ray>
                <scan>
                    <horizontal>
                        <samples>720</samples>
                        <resolution>1</resolution>
                        <min_angle>-1.48353</min_angle>
                        <max_angle>1.48353</max_angle>
                    </horizontal>
                </scan>
                <range>
                    <min>0.10</min>
                    <max>30.0</max>
                    <resolution>0.05</resolution>
                </range>
                <noise>
                    <type>gaussian</type>
                    <!-- Noise parameters based on published spec for Hokuyo laser
                   achieving "+-30mm" accuracy at range < 10m.  A mean of 0.0m and
                   stddev of 0.01m will put 99.7% of samples within 0.03m of the true
                   reading. -->
                    <mean>0.0</mean>
                    <stddev>0.01</stddev>
                </noise>
            </ray>
            <plugin filename="libgazebo_ros_laser.so" name="lidar_1">
                <topicName>lidar_1/scan_filtered</topicName>
                <frameName>lidar_1_link</frameName>
            </plugin>
        </sensor>
    </gazebo>
    <gazebo reference="lidar_2_link">
        <sensor name="lidar_2_sensor" type="ray">
            <pose>0 0 0 0 0 0</pose>
            <visualize>false</visualize>
            <update_rate>40</update_rate>
            <ray>
                <scan>
                    <horizontal>
                        <samples>720</samples>
                        <resolution>1</resolution>
                        <min_angle>-1.48353</min_angle>
                        <max_angle>1.48353</max_angle>
                    </horizontal>
                </scan>
                <range>
                    <min>0.10</min>
                    <max>30.0</max>
                    <resolution>0.05</resolution>
                </range>
                <noise>
                    <type>gaussian</type>
                    <!-- Noise parameters based on published spec for Hokuyo laser
                   achieving "+-30mm" accuracy at range < 10m.  A mean of 0.0m and
                   stddev of 0.01m will put 99.7% of samples within 0.03m of the true
                   reading. -->
                    <mean>0.0</mean>
                    <stddev>0.01</stddev>
                </noise>
            </ray>
            <plugin filename="libgazebo_ros_laser.so" name="lidar_2">
                <topicName>lidar_2/scan_filtered</topicName>
                <frameName>lidar_2_link</frameName>
            </plugin>
        </sensor>
    </gazebo>
    <!-- IMU sensor -->
    <gazebo reference="imu_link">
        <gravity>true</gravity>
        <sensor name="imu_sensor" type="imu">
            <always_on>true</always_on>
            <update_rate>100</update_rate>
            <visualize>true</visualize>
            <topic>__default_topic__</topic>
            <plugin filename="libgazebo_ros_imu_sensor.so" name="imu_plugin">
                <topicName>imu</topicName>
                <bodyName>imu_link</bodyName>
                <updateRateHZ>10.0</updateRateHZ>
                <gaussianNoise>0.0</gaussianNoise>
                <xyzOffset>0 0 0</xyzOffset>
                <rpyOffset>0 0 0</rpyOffset>
                <frameName>imu_link</frameName>
            </plugin>
            <pose>0 0 0 0 0 0</pose>
        </sensor>
    </gazebo>
    <!-- Ultrasonic sensors -->
    <gazebo reference="us_1_link">
        <!-- Visuals / Collisions omitted for this example -->
        <sensor name="range" type="ray">
            <ray>
                <scan>
                    <horizontal>
                        <samples>1</samples>
                        <resolution>1.0</resolution>
                        <min_angle>-0.01</min_angle>
                        <max_angle>0.01</max_angle>
                    </horizontal>
                    <vertical>
                        <samples>1</samples>
                        <resolution>1</resolution>
                        <min_angle>-0.01</min_angle>
                        <max_angle>0.01</max_angle>
                    </vertical>
                </scan>
                <range>
                    <min>0.01</min>
                    <max>3.75</max>
                    <resolution>0.02</resolution>
                </range>
            </ray>
            <plugin filename="libgazebo_ros_range.so" name="libgazebo_ros_range">
                <gaussianNoise>0.005</gaussianNoise>
                <alwaysOn>true</alwaysOn>
                <updateRate>50</updateRate>
                <topicName>us_sensor</topicName>
                <frameName>us_1_link</frameName>
                <radiation>SONAR</radiation>
                <fov>0.2967</fov>
            </plugin>
        </sensor>
    </gazebo>
    <!-- camera -->
    <gazebo reference="camera_link">
        <sensor name="camera1" type="camera">
            <update_rate>30.0</update_rate>
            <camera name="head">
                <horizontal_fov>1.3962634</horizontal_fov>
                <image>
                    <width>800</width>
                    <height>800</height>
                    <format>R8G8B8</format>
                </image>
                <clip>
                    <near>0.02</near>
                    <far>300</far>
                </clip>
                <noise>
                    <type>gaussian</type>
                    <!-- Noise is sampled independently per pixel on each frame.
               That pixel's noise value is added to each of its color
               channels, which at that point lie in the range [0,1]. -->
                    <mean>0.0</mean>
                    <stddev>0.007</stddev>
                </noise>
            </camera>
            <plugin filename="libgazebo_ros_camera.so" name="camera_controller">
                <alwaysOn>true</alwaysOn>
                <updateRate>0.0</updateRate>
                <cameraName>camera1</cameraName>
                <imageTopicName>image_raw</imageTopicName>
                <cameraInfoTopicName>camera_info</cameraInfoTopicName>
                <frameName>camera_link</frameName>
                <hackBaseline>0.07</hackBaseline>
                <distortionK1>0.0</distortionK1>
                <distortionK2>0.0</distortionK2>
                <distortionK3>0.0</distortionK3>
                <distortionT1>0.0</distortionT1>
                <distortionT2>0.0</distortionT2>
            </plugin>
        </sensor>
    </gazebo>
    <gazebo>
        <plugin filename="libgazebo_ros_planar_move.so" name="mpo_500_controller">
            <commandTopic>cmd_vel</commandTopic>
            <odometryTopic>odom</odometryTopic>
            <odometryFrame>odom</odometryFrame>
            <odometryRate>20.0</odometryRate>
            <robotBaseFrame>base_link</robotBaseFrame>
        </plugin>
    </gazebo>
    <gazebo>
        <plugin filename="libgazebo_ros_control.so" name="ros_control">
            <legacyModeNS>false</legacyModeNS>
            <robotSimType>gazebo_ros_control/DefaultRobotHWSim</robotSimType>
        </plugin>
    </gazebo>
    <gazebo>
        <plugin filename="libgazebo_ros_moveit_planning_scene.so" name="gazebo_ros_moveit_planning_scene">
            <topicName>/planning_scene</topicName>
            <sceneName>laboratory</sceneName>
            <robotName>mmo_500</robotName>
            <updatePeriod>0.5</updatePeriod>
        </plugin>
    </gazebo>
    <gazebo>
        <plugin filename="libgazebo_grasp_fix.so" name="gazebo_grasp_fix">
            <arm>
                <arm_name>arm</arm_name>
                <palm_link>wrist_3_link</palm_link>
                <gripper_link>H1_F1_link_1</gripper_link>
                <gripper_link>H1_F2_link_1</gripper_link>
                <gripper_link>H1_F3_link_1</gripper_link>
                <gripper_link>H1_F1_link_2</gripper_link>
                <gripper_link>H1_F2_link_2</gripper_link>
                <gripper_link>H1_F3_link_2</gripper_link>
            </arm>
            <forces_angle_tolerance>100</forces_angle_tolerance>
            <update_rate>4</update_rate>
            <grip_count_threshold>4</grip_count_threshold>
            <max_grip_count>20</max_grip_count>
            <release_tolerance>0.005</release_tolerance>
            <disable_collisions_on_attach>false</disable_collisions_on_attach>
            <contact_topic>__default_topic__</contact_topic>
        </plugin>
    </gazebo>
    <link name="base_link">
        
<inertial>
            <mass value="80" />
            <origin xyz="0 0.0 0.0" />
            <inertia ixx="2.8" ixy="0.0" ixz="0.0" iyy="2.8" iyz="0.0" izz="2.8" />
        </inertial>

        <visual>
            <origin rpy="-1.571 0 1.571" xyz="0. 0. 0" />
            <geometry>
                <mesh filename="package://gazebo_simulation/robots/meshes/MPO-500-BODY.dae" scale="0.001 0.001 0.001" />
            </geometry>
        </visual>
        <collision>
            <origin rpy="-1.571 0 1.571" xyz="0. 0. 0.0" />
            <geometry>
                <!--<box size="0.68 0.41 0.25"/> -->
                <mesh filename="package://gazebo_simulation/robots/meshes/MPO-500-BODY.dae" scale="0.001 0.001 0.001" />
            </geometry>
        </collision>
    </link>
    <joint name="mpo_500_omni_wheel_front_left_joint" type="continuous">
        <origin rpy="0 0 0" xyz="0.25 0.28 0.13" />
        <axis xyz="0 1 0" />
        <joint_properties damping="100" friction="100" />
        <parent link="base_link" />
        <child link="mpo_500_omni_wheel_front_left_link" />
    </joint>
    <link name="mpo_500_omni_wheel_front_left_link" type="wheel">
        
<inertial>
            <mass value="4.2" />
            <origin rpy="0 0 0" xyz="0 0 0" />
            <inertia ixx="0.0338" ixy="0.0" ixz="0.0" iyy="0.0338" iyz="0.0" izz="0.0338" />
        </inertial>

        <visual>
            <origin rpy="0 0 0" xyz="0 0 0" />
            <geometry>
                <mesh filename="package://gazebo_simulation/robots/meshes/MPO-500-WHEEL.dae" scale="0.001 0.001 0.001" />
            </geometry>
        </visual>
        <collision>
            <origin rpy="1.57 0 0" xyz="0 0 0" />
            <geometry>
                <sphere radius="0.127" />
            </geometry>
        </collision>
    </link>
    <gazebo reference="mpo_500_omni_wheel_front_left_link">
        <mu1>0.045</mu1>
        <mu2>0.045</mu2>
    </gazebo>
    <joint name="mpo_500_omni_wheel_front_right_joint" type="continuous">
        <origin rpy="0 0 3.14" xyz="0.25 -0.28 0.13" />
        <axis xyz="0 1 0" />
        <joint_properties damping="100" friction="100" />
        <parent link="base_link" />
        <child link="mpo_500_omni_wheel_front_right_link" />
    </joint>
    <link name="mpo_500_omni_wheel_front_right_link" type="wheel">
        
<inertial>
            <mass value="4.2" />
            <origin rpy="0 0 0" xyz="0 0 0" />
            <inertia ixx="0.0338" ixy="0.0" ixz="0.0" iyy="0.0338" iyz="0.0" izz="0.0338" />
        </inertial>

        <visual>
            <origin rpy="0 0 0" xyz="0 0 0" />
            <geometry>
                <mesh filename="package://gazebo_simulation/robots/meshes/MPO-500-WHEEL.dae" scale="0.001 0.001 0.001" />
            </geometry>
        </visual>
        <collision>
            <origin rpy="1.57 0 0" xyz="0 0 0" />
            <geometry>
                <sphere radius="0.127" />
            </geometry>
        </collision>
    </link>
    <gazebo reference="mpo_500_omni_wheel_front_right_link">
        <mu1>0.045</mu1>
        <mu2>0.045</mu2>
    </gazebo>
    <joint name="mpo_500_omni_wheel_back_left_joint" type="continuous">
        <origin rpy="0 0 0" xyz="-0.25 0.28 0.13" />
        <axis xyz="0 1 0" />
        <joint_properties damping="100" friction="100" />
        <parent link="base_link" />
        <child link="mpo_500_omni_wheel_back_left_link" />
    </joint>
    <link name="mpo_500_omni_wheel_back_left_link" type="wheel">
        
<inertial>
            <mass value="4.2" />
            <origin rpy="0 0 0" xyz="0 0 0" />
            <inertia ixx="0.0338" ixy="0.0" ixz="0.0" iyy="0.0338" iyz="0.0" izz="0.0338" />
        </inertial>

        <visual>
            <origin rpy="0 0 0" xyz="0 0 0" />
            <geometry>
                <mesh filename="package://gazebo_simulation/robots/meshes/MPO-500-WHEEL.dae" scale="0.001 0.001 0.001" />
            </geometry>
        </visual>
        <collision>
            <origin rpy="1.57 0 0" xyz="0 0 0" />
            <geometry>
                <sphere radius="0.127" />
            </geometry>
        </collision>
    </link>
    <gazebo reference="mpo_500_omni_wheel_back_left_link">
        <mu1>0.045</mu1>
        <mu2>0.045</mu2>
    </gazebo>
    <joint name="mpo_500_omni_wheel_back_right_joint" type="continuous">
        <origin rpy="0 0 3.14" xyz="-0.25 -0.28 0.13" />
        <axis xyz="0 1 0" />
        <joint_properties damping="100" friction="100" />
        <parent link="base_link" />
        <child link="mpo_500_omni_wheel_back_right_link" />
    </joint>
    <link name="mpo_500_omni_wheel_back_right_link" type="wheel">
        
<inertial>
            <mass value="4.2" />
            <origin rpy="0 0 0" xyz="0 0 0" />
            <inertia ixx="0.0338" ixy="0.0" ixz="0.0" iyy="0.0338" iyz="0.0" izz="0.0338" />
        </inertial>

        <visual>
            <origin rpy="0 0 0" xyz="0 0 0" />
            <geometry>
                <mesh filename="package://gazebo_simulation/robots/meshes/MPO-500-WHEEL.dae" scale="0.001 0.001 0.001" />
            </geometry>
        </visual>
        <collision>
            <origin rpy="1.57 0 0" xyz="0 0 0" />
            <geometry>
                <sphere radius="0.127" />
            </geometry>
        </collision>
    </link>
    <gazebo reference="mpo_500_omni_wheel_back_right_link">
        <mu1>0.045</mu1>
        <mu2>0.045</mu2>
    </gazebo>
    <!--joint name="cabinet_joints" type="fixed">
      <parent link="${parent}" />
      <child link = "pilzbase_link" />
      <origin xyz="-0.05 0.0 0.12" rpy="0.0 0.0 0.0" />
    </joint-->
    <joint name="mpo_joint" type="fixed">
        <parent link="base_link" />
        <child link="prbt_base_link" />
        <origin rpy="0 0 3.1415" xyz="0.2 0 0.39" />
    </joint>
    <!-- robot foot link -->
    <link name="prbt_base_link">
        
<inertial>
            <mass value="2.4" />
            <inertia ixx="0" ixy="0" ixz="0" iyy="0" iyz="0" izz="0" />
        </inertial>

        <visual>
            <origin rpy="0 0 0" xyz="0 0 0" />
            <geometry>
                <mesh filename="package://gazebo_simulation/robots/meshes/foot.dae" />
            </geometry>
        </visual>
        <collision>
            <origin rpy="3.14159265359 0 0" xyz="0 0 0.065" />
            <geometry>
                <cylinder length="0.13" radius="0.09275" />
            </geometry>
        </collision>
    </link>
    <!-- arm 1 joint -->
    <joint name="prbt_joint_1" type="revolute">
        <origin rpy="0 0 -3.14159265359" xyz="0 0 0.2604" />
        <parent link="prbt_base_link" />
        <child link="prbt_link_1" />
        <axis xyz="0 0 1" />
        <limit effort="370" lower="-2.96706" upper="2.96706" velocity="1.57" />
        <dynamics damping="15.0" friction="11" />
    </joint>
    <!-- arm 1 link -->
    <link name="prbt_link_1">
        
<inertial>
            <mass value="7.1" />
            <origin xyz="0 -0.026 -0.051" />
            <inertia ixx="3.53e-2" ixy="0" ixz="0" iyy="3.01e-2" iyz="9.04e-3" izz="1.87e-2" />
        </inertial>

        <visual>
            <origin rpy="0 0 0" xyz="0 0 0" />
            <geometry>
                <mesh filename="package://gazebo_simulation/robots/meshes/link_1.dae" />
            </geometry>
        </visual>
        <collision>
            <origin rpy="0 0 0" xyz="0 0 -0.08" />
            <geometry>
                <cylinder length="0.10" radius="0.07" />
            </geometry>
        </collision>
        <collision>
            <origin rpy="0 0 0" xyz="0 0 0" />
            <geometry>
                <sphere radius="0.09" />
            </geometry>
        </collision>
        <collision>
            <origin rpy="0 1.57079632679 1.57079632679" xyz="0 -0.10 0" />
            <geometry>
                <cylinder length="0.10" radius="0.065" />
            </geometry>
        </collision>
    </link>
    <!-- joint between arm_1_link and arm_2_link -->
    <joint name="prbt_joint_2" type="revolute">
        <origin rpy="1.57079632679 0 0" xyz="0 0 0" />
        <parent link="prbt_link_1" />
        <child link="prbt_link_2" />
        <axis xyz="0 0 1" />
        <limit effort="370" lower="-2.53073" upper="2.53073" velocity="1.57" />
        <dynamics damping="12.0" friction="10.0" />
    </joint>
    <link name="prbt_link_2">
        
<inertial>
            <mass value="1.7" />
            <origin xyz="0 0.162 0.134" />
            <inertia ixx="3.58e-2" ixy="0" ixz="0" iyy="3.22e-3" iyz="-1.45e-3" izz="3.66e-2" />
        </inertial>

        <visual name="first">
            <origin rpy="0 0 0" xyz="0 0 0" />
            <geometry>
                <mesh filename="package://gazebo_simulation/robots/meshes/link_2.dae" />
            </geometry>
        </visual>
        <collision>
            <origin rpy="0.174532925199 0 0" xyz="0 0.15 0.145" />
            <geometry>
                <box size="0.121 0.27 0.065" />
            </geometry>
        </collision>
        <collision>
            <origin rpy="-0.448798950513 0 0" xyz="0 0.3 0.145" />
            <geometry>
                <box size="0.11 0.1 0.075" />
            </geometry>
        </collision>
    </link>
    <!-- joint between arm_2_link and arm_3_link -->
    <joint name="prbt_joint_3" type="revolute">
        <origin rpy="0 3.14159265359 0" xyz="0 0.35 0" />
        <parent link="prbt_link_2" />
        <child link="prbt_link_3" />
        <axis xyz="0 0 1" />
        <limit effort="176" lower="-2.35620" upper="2.35620" velocity="1.57" />
        <dynamics damping="4.5" friction="4.5" />
    </joint>
    <link name="prbt_link_3">
        
<inertial>
            <mass value="4.8" />
            <origin xyz="0 0.043 -0.027" />
            <inertia ixx="2.06e-2" ixy="0" ixz="0" iyy="1.08e-2" iyz="-5.36e-3" izz="1.63e-2" />
        </inertial>

        <visual>
            <origin rpy="0 0 0" xyz="0 0 0" />
            <geometry>
                <mesh filename="package://gazebo_simulation/robots/meshes/link_3.dae" />
            </geometry>
        </visual>
        <collision>
            <origin rpy="0 0 0" xyz="0 0 -0.11" />
            <geometry>
                <cylinder length="0.10" radius="0.06" />
            </geometry>
        </collision>
        <collision>
            <origin rpy="0 0 0" xyz="0 0 0" />
            <geometry>
                <sphere radius="0.085" />
            </geometry>
        </collision>
        <collision>
            <origin rpy="0 1.57079632679 1.57079632679" xyz="0 0.10 0" />
            <geometry>
                <cylinder length="0.10" radius="0.065" />
            </geometry>
        </collision>
    </link>
    <!-- joint between arm_3_link and arm_4_link -->
    <joint name="prbt_joint_4" type="revolute">
        <origin rpy="-1.57079632679 3.14159265359 0" xyz="0 0 0" />
        <parent link="prbt_link_3" />
        <child link="prbt_link_4" />
        <axis xyz="0 0 1" />
        <limit effort="176" lower="-2.96706" upper="2.96706" velocity="1.57" />
        <dynamics damping="4.2" friction="3.8" />
    </joint>
    <link name="prbt_link_4">
        
<inertial>
            <mass value="0.9" />
            <origin xyz="0 -0.061 0.204" />
            <inertia ixx="6.79e-3" ixy="0" ixz="0" iyy="4.91e-3" iyz="2.67e-3" izz="3.40e-3" />
        </inertial>

        <visual>
            <origin rpy="0 0 0" xyz="0 0 0" />
            <geometry>
                <mesh filename="package://gazebo_simulation/robots/meshes/link_4.dae" />
            </geometry>
        </visual>
        <collision>
            <origin rpy="0.966643893412 0 0" xyz="0 -0.04 0.162" />
            <geometry>
                <box size="0.121 0.08 0.17" />
            </geometry>
        </collision>
        <collision>
            <origin rpy="-0.10471975512 0 0" xyz="0 -0.115 0.25" />
            <geometry>
                <box size="0.09 0.06 0.12" />
            </geometry>
        </collision>
    </link>
    <!-- joint between arm_4_link and arm_5_link -->
    <joint name="prbt_joint_5" type="revolute">
        <origin rpy="1.57079632679 0 3.14159265359" xyz="0 0 0.307" />
        <parent link="prbt_link_4" />
        <child link="prbt_link_5" />
        <axis xyz="0 0 1" />
        <limit effort="41.6" lower="-2.967" upper="2.967" velocity="1.57" />
        <dynamics damping="1.5" friction="3.5" />
    </joint>
    <link name="prbt_link_5">
        
<inertial>
            <mass value="2.6" />
            <origin xyz="-0.001 0.021 -0.032" />
            <inertia ixx="7.37e-3" ixy="4.78e-6" ixz="6.00e-5" iyy="5.87e-3" iyz="-1.71e-3" izz="3.96e-3" />
        </inertial>

        <visual>
            <origin rpy="0 0 0" xyz="0 0 0" />
            <geometry>
                <mesh filename="package://gazebo_simulation/robots/meshes/link_5.dae" />
            </geometry>
        </visual>
        <collision>
            <origin rpy="0 0 0" xyz="0 0 -0.095" />
            <geometry>
                <cylinder length="0.08" radius="0.045" />
            </geometry>
        </collision>
        <collision>
            <origin rpy="0 0 0" xyz="0 0 -0.06" />
            <geometry>
                <cylinder length="0.04" radius="0.0545" />
            </geometry>
        </collision>
        <collision>
            <origin rpy="0 0 0" xyz="0 0 0" />
            <geometry>
                <sphere radius="0.07" />
            </geometry>
        </collision>
        <collision>
            <origin rpy="0 1.57079632679 1.57079632679" xyz="0 0.05 0" />
            <geometry>
                <cylinder length="0.03" radius="0.05" />
            </geometry>
        </collision>
        <collision>
            <origin rpy="0 1.57079632679 1.57079632679" xyz="0 0.05 0" />
            <geometry>
                <cylinder length="0.049" radius="0.0435" />
            </geometry>
        </collision>
    </link>
    <!-- joint between arm_5_link and flange -->
    <joint name="prbt_joint_6" type="revolute">
        <origin rpy="-1.57079632679 0 0" xyz="0 0.084 0" />
        <parent link="prbt_link_5" />
        <child link="prbt_flange" />
        <axis xyz="0 0 1" />
        <limit effort="20.1" lower="-3.12414" upper="3.12414" velocity="1.57" />
        <dynamics damping="4.5" friction="7.0" />
    </joint>
    <!-- Flange -->
    <link name="prbt_flange">
        
<inertial>
            <mass value="0.02" />
            <origin xyz="0 0 0" />
            <inertia ixx="0" ixy="0" ixz="0" iyy="0" iyz="0" izz="0" />
        </inertial>

        <visual>
            <origin rpy="0 0 0" xyz="0 0 0" />
            <geometry>
                <mesh filename="package://gazebo_simulation/robots/meshes/flange.dae" />
            </geometry>
        </visual>
        <collision>
            <origin rpy="0 0 0" xyz="0 0 -0.0035" />
            <geometry>
                <cylinder length="0.02" radius="0.0331" />
            </geometry>
        </collision>
    </link>
    <!-- ROS-Industrial 'base' frame: base_link to robot world coordinate sytem transform -->
    <link name="prbt_base" />
    <joint name="prbt_base_link-base" type="fixed">
        <origin rpy="0 0 0" xyz="0 0 0" />
        <parent link="prbt_base_link" />
        <child link="prbt_base" />
    </joint>
    <!-- ROS-Industrial 'tool0' frame: all-zeros tool frame -->
    <link name="prbt_tool0" />
    <joint name="prbt_flange-tool0" type="fixed">
        <origin rpy="0 0 0" xyz="0 0 0" />
        <parent link="prbt_flange" />
        <child link="prbt_tool0" />
    </joint>
    <!-- transmissions for gazebo -->
    
<transmission name="prbt_joint_1_trans">
        <type>transmission_interface/SimpleTransmission</type>
        <joint name="prbt_joint_1">
            <hardwareInterface>hardware_interface/PositionJointInterface</hardwareInterface>
        </joint>
        <actuator name="prbt_joint_1_motor" />
    </transmission>
    <transmission name="prbt_joint_2_trans">
        <type>transmission_interface/SimpleTransmission</type>
        <joint name="prbt_joint_2">
            <hardwareInterface>hardware_interface/PositionJointInterface</hardwareInterface>
        </joint>
        <actuator name="prbt_joint_2_motor" />
    </transmission>
    <transmission name="prbt_joint_3_trans">
        <type>transmission_interface/SimpleTransmission</type>
        <joint name="prbt_joint_3">
            <hardwareInterface>hardware_interface/PositionJointInterface</hardwareInterface>
        </joint>
        <actuator name="prbt_joint_3_motor" />
    </transmission>
    <transmission name="prbt_joint_4_trans">
        <type>transmission_interface/SimpleTransmission</type>
        <joint name="prbt_joint_4">
            <hardwareInterface>hardware_interface/PositionJointInterface</hardwareInterface>
        </joint>
        <actuator name="prbt_joint_4_motor" />
    </transmission>
    <transmission name="prbt_joint_5_trans">
        <type>transmission_interface/SimpleTransmission</type>
        <joint name="prbt_joint_5">
            <hardwareInterface>hardware_interface/PositionJointInterface</hardwareInterface>
        </joint>
        <actuator name="prbt_joint_5_motor" />
    </transmission>
    <transmission name="prbt_joint_6_trans">
        <type>transmission_interface/SimpleTransmission</type>
        <joint name="prbt_joint_6">
            <hardwareInterface>hardware_interface/PositionJointInterface</hardwareInterface>
        </joint>
        <actuator name="prbt_joint_6_motor" />
    </transmission>
    <transmission name="trans_mpo_500_omni_wheel_front_left_joint">
        <type>transmission_interface/SimpleTransmission</type>
        <joint name="mpo_500_omni_wheel_front_left_joint">
            <hardwareInterface>hardware_interface/EffortJointInterface</hardwareInterface>
        </joint>
        <actuator name="mpo_500_omni_wheel_front_left_joint_motor">
            <hardwareInterface>hardware_interface/EffortJointInterface</hardwareInterface>
            <mechanicalReduction>1</mechanicalReduction>
        </actuator>
    </transmission>
    <transmission name="trans_mpo_500_omni_wheel_front_right_joint">
        <type>transmission_interface/SimpleTransmission</type>
        <joint name="mpo_500_omni_wheel_front_right_joint">
            <hardwareInterface>hardware_interface/EffortJointInterface</hardwareInterface>
        </joint>
        <actuator name="mpo_500_omni_wheel_front_right_joint_motor">
            <hardwareInterface>hardware_interface/EffortJointInterface</hardwareInterface>
            <mechanicalReduction>1</mechanicalReduction>
        </actuator>
    </transmission>
    <transmission name="trans_mpo_500_omni_wheel_back_left_joint">
        <type>transmission_interface/SimpleTransmission</type>
        <joint name="mpo_500_omni_wheel_back_left_joint">
            <hardwareInterface>hardware_interface/EffortJointInterface</hardwareInterface>
        </joint>
        <actuator name="mpo_500_omni_wheel_back_left_joint_motor">
            <hardwareInterface>hardware_interface/EffortJointInterface</hardwareInterface>
            <mechanicalReduction>1</mechanicalReduction>
        </actuator>
    </transmission>
    <transmission name="trans_mpo_500_omni_wheel_back_right_joint">
        <type>transmission_interface/SimpleTransmission</type>
        <joint name="mpo_500_omni_wheel_back_right_joint">
            <hardwareInterface>hardware_interface/EffortJointInterface</hardwareInterface>
        </joint>
        <actuator name="mpo_500_omni_wheel_back_right_joint_motor">
            <hardwareInterface>hardware_interface/EffortJointInterface</hardwareInterface>
            <mechanicalReduction>1</mechanicalReduction>
        </actuator>
    </transmission>
    <transmission name="trans_prbt_joint_1">
        <type>transmission_interface/SimpleTransmission</type>
        <joint name="prbt_joint_1">
            <hardwareInterface>hardware_interface/EffortJointInterface</hardwareInterface>
        </joint>
        <actuator name="prbt_joint_1_motor">
            <hardwareInterface>hardware_interface/EffortJointInterface</hardwareInterface>
            <mechanicalReduction>1</mechanicalReduction>
        </actuator>
    </transmission>
    <transmission name="trans_prbt_joint_2">
        <type>transmission_interface/SimpleTransmission</type>
        <joint name="prbt_joint_2">
            <hardwareInterface>hardware_interface/EffortJointInterface</hardwareInterface>
        </joint>
        <actuator name="prbt_joint_2_motor">
            <hardwareInterface>hardware_interface/EffortJointInterface</hardwareInterface>
            <mechanicalReduction>1</mechanicalReduction>
        </actuator>
    </transmission>
    <transmission name="trans_prbt_joint_3">
        <type>transmission_interface/SimpleTransmission</type>
        <joint name="prbt_joint_3">
            <hardwareInterface>hardware_interface/EffortJointInterface</hardwareInterface>
        </joint>
        <actuator name="prbt_joint_3_motor">
            <hardwareInterface>hardware_interface/EffortJointInterface</hardwareInterface>
            <mechanicalReduction>1</mechanicalReduction>
        </actuator>
    </transmission>
    <transmission name="trans_prbt_joint_4">
        <type>transmission_interface/SimpleTransmission</type>
        <joint name="prbt_joint_4">
            <hardwareInterface>hardware_interface/EffortJointInterface</hardwareInterface>
        </joint>
        <actuator name="prbt_joint_4_motor">
            <hardwareInterface>hardware_interface/EffortJointInterface</hardwareInterface>
            <mechanicalReduction>1</mechanicalReduction>
        </actuator>
    </transmission>
    <transmission name="trans_prbt_joint_5">
        <type>transmission_interface/SimpleTransmission</type>
        <joint name="prbt_joint_5">
            <hardwareInterface>hardware_interface/EffortJointInterface</hardwareInterface>
        </joint>
        <actuator name="prbt_joint_5_motor">
            <hardwareInterface>hardware_interface/EffortJointInterface</hardwareInterface>
            <mechanicalReduction>1</mechanicalReduction>
        </actuator>
    </transmission>
    <transmission name="trans_prbt_joint_6">
        <type>transmission_interface/SimpleTransmission</type>
        <joint name="prbt_joint_6">
            <hardwareInterface>hardware_interface/EffortJointInterface</hardwareInterface>
        </joint>
        <actuator name="prbt_joint_6_motor">
            <hardwareInterface>hardware_interface/EffortJointInterface</hardwareInterface>
            <mechanicalReduction>1</mechanicalReduction>
        </actuator>
    </transmission>
    <gazebo>
        <plugin filename="libgazebo_ros_control.so" name="gazebo_ros_control">
            <robotNamespace>/</robotNamespace>
        </plugin>
    </gazebo>
    <transmission name="trans_mpo_500_omni_wheel_front_left_joint">
        <type>transmission_interface/SimpleTransmission</type>
        <joint name="mpo_500_omni_wheel_front_left_joint">
            <hardwareInterface>hardware_interface/EffortJointInterface</hardwareInterface>
        </joint>
        <actuator name="mpo_500_omni_wheel_front_left_joint_motor">
            <hardwareInterface>hardware_interface/EffortJointInterface</hardwareInterface>
            <mechanicalReduction>1</mechanicalReduction>
        </actuator>
    </transmission>
    <transmission name="trans_mpo_500_omni_wheel_front_right_joint">
        <type>transmission_interface/SimpleTransmission</type>
        <joint name="mpo_500_omni_wheel_front_right_joint">
            <hardwareInterface>hardware_interface/EffortJointInterface</hardwareInterface>
        </joint>
        <actuator name="mpo_500_omni_wheel_front_right_joint_motor">
            <hardwareInterface>hardware_interface/EffortJointInterface</hardwareInterface>
            <mechanicalReduction>1</mechanicalReduction>
        </actuator>
    </transmission>
    <transmission name="trans_mpo_500_omni_wheel_back_left_joint">
        <type>transmission_interface/SimpleTransmission</type>
        <joint name="mpo_500_omni_wheel_back_left_joint">
            <hardwareInterface>hardware_interface/EffortJointInterface</hardwareInterface>
        </joint>
        <actuator name="mpo_500_omni_wheel_back_left_joint_motor">
            <hardwareInterface>hardware_interface/EffortJointInterface</hardwareInterface>
            <mechanicalReduction>1</mechanicalReduction>
        </actuator>
    </transmission>
    <transmission name="trans_mpo_500_omni_wheel_back_right_joint">
        <type>transmission_interface/SimpleTransmission</type>
        <joint name="mpo_500_omni_wheel_back_right_joint">
            <hardwareInterface>hardware_interface/EffortJointInterface</hardwareInterface>
        </joint>
        <actuator name="mpo_500_omni_wheel_back_right_joint_motor">
            <hardwareInterface>hardware_interface/EffortJointInterface</hardwareInterface>
            <mechanicalReduction>1</mechanicalReduction>
        </actuator>
    </transmission>
    <transmission name="trans_prbt_joint_1">
        <type>transmission_interface/SimpleTransmission</type>
        <joint name="prbt_joint_1">
            <hardwareInterface>hardware_interface/EffortJointInterface</hardwareInterface>
        </joint>
        <actuator name="prbt_joint_1_motor">
            <hardwareInterface>hardware_interface/EffortJointInterface</hardwareInterface>
            <mechanicalReduction>1</mechanicalReduction>
        </actuator>
    </transmission>
    <transmission name="trans_prbt_joint_2">
        <type>transmission_interface/SimpleTransmission</type>
        <joint name="prbt_joint_2">
            <hardwareInterface>hardware_interface/EffortJointInterface</hardwareInterface>
        </joint>
        <actuator name="prbt_joint_2_motor">
            <hardwareInterface>hardware_interface/EffortJointInterface</hardwareInterface>
            <mechanicalReduction>1</mechanicalReduction>
        </actuator>
    </transmission>
    <transmission name="trans_prbt_joint_3">
        <type>transmission_interface/SimpleTransmission</type>
        <joint name="prbt_joint_3">
            <hardwareInterface>hardware_interface/EffortJointInterface</hardwareInterface>
        </joint>
        <actuator name="prbt_joint_3_motor">
            <hardwareInterface>hardware_interface/EffortJointInterface</hardwareInterface>
            <mechanicalReduction>1</mechanicalReduction>
        </actuator>
    </transmission>
    <transmission name="trans_prbt_joint_4">
        <type>transmission_interface/SimpleTransmission</type>
        <joint name="prbt_joint_4">
            <hardwareInterface>hardware_interface/EffortJointInterface</hardwareInterface>
        </joint>
        <actuator name="prbt_joint_4_motor">
            <hardwareInterface>hardware_interface/EffortJointInterface</hardwareInterface>
            <mechanicalReduction>1</mechanicalReduction>
        </actuator>
    </transmission>
    <transmission name="trans_prbt_joint_5">
        <type>transmission_interface/SimpleTransmission</type>
        <joint name="prbt_joint_5">
            <hardwareInterface>hardware_interface/EffortJointInterface</hardwareInterface>
        </joint>
        <actuator name="prbt_joint_5_motor">
            <hardwareInterface>hardware_interface/EffortJointInterface</hardwareInterface>
            <mechanicalReduction>1</mechanicalReduction>
        </actuator>
    </transmission>
    <transmission name="trans_prbt_joint_6">
        <type>transmission_interface/SimpleTransmission</type>
        <joint name="prbt_joint_6">
            <hardwareInterface>hardware_interface/EffortJointInterface</hardwareInterface>
        </joint>
        <actuator name="prbt_joint_6_motor">
            <hardwareInterface>hardware_interface/EffortJointInterface</hardwareInterface>
            <mechanicalReduction>1</mechanicalReduction>
        </actuator>
    </transmission>
    <gazebo>
        <plugin filename="libgazebo_ros_control.so" name="gazebo_ros_control">
            <robotNamespace>/</robotNamespace>
        </plugin>
    </gazebo>
    <transmission name="trans_mpo_500_omni_wheel_front_left_joint">
        <type>transmission_interface/SimpleTransmission</type>
        <joint name="mpo_500_omni_wheel_front_left_joint">
            <hardwareInterface>hardware_interface/EffortJointInterface</hardwareInterface>
        </joint>
        <actuator name="mpo_500_omni_wheel_front_left_joint_motor">
            <hardwareInterface>hardware_interface/EffortJointInterface</hardwareInterface>
            <mechanicalReduction>1</mechanicalReduction>
        </actuator>
    </transmission>
    <transmission name="trans_mpo_500_omni_wheel_front_right_joint">
        <type>transmission_interface/SimpleTransmission</type>
        <joint name="mpo_500_omni_wheel_front_right_joint">
            <hardwareInterface>hardware_interface/EffortJointInterface</hardwareInterface>
        </joint>
        <actuator name="mpo_500_omni_wheel_front_right_joint_motor">
            <hardwareInterface>hardware_interface/EffortJointInterface</hardwareInterface>
            <mechanicalReduction>1</mechanicalReduction>
        </actuator>
    </transmission>
    <transmission name="trans_mpo_500_omni_wheel_back_left_joint">
        <type>transmission_interface/SimpleTransmission</type>
        <joint name="mpo_500_omni_wheel_back_left_joint">
            <hardwareInterface>hardware_interface/EffortJointInterface</hardwareInterface>
        </joint>
        <actuator name="mpo_500_omni_wheel_back_left_joint_motor">
            <hardwareInterface>hardware_interface/EffortJointInterface</hardwareInterface>
            <mechanicalReduction>1</mechanicalReduction>
        </actuator>
    </transmission>
    <transmission name="trans_mpo_500_omni_wheel_back_right_joint">
        <type>transmission_interface/SimpleTransmission</type>
        <joint name="mpo_500_omni_wheel_back_right_joint">
            <hardwareInterface>hardware_interface/EffortJointInterface</hardwareInterface>
        </joint>
        <actuator name="mpo_500_omni_wheel_back_right_joint_motor">
            <hardwareInterface>hardware_interface/EffortJointInterface</hardwareInterface>
            <mechanicalReduction>1</mechanicalReduction>
        </actuator>
    </transmission>
    <transmission name="trans_prbt_joint_1">
        <type>transmission_interface/SimpleTransmission</type>
        <joint name="prbt_joint_1">
            <hardwareInterface>hardware_interface/EffortJointInterface</hardwareInterface>
        </joint>
        <actuator name="prbt_joint_1_motor">
            <hardwareInterface>hardware_interface/EffortJointInterface</hardwareInterface>
            <mechanicalReduction>1</mechanicalReduction>
        </actuator>
    </transmission>
    <transmission name="trans_prbt_joint_2">
        <type>transmission_interface/SimpleTransmission</type>
        <joint name="prbt_joint_2">
            <hardwareInterface>hardware_interface/EffortJointInterface</hardwareInterface>
        </joint>
        <actuator name="prbt_joint_2_motor">
            <hardwareInterface>hardware_interface/EffortJointInterface</hardwareInterface>
            <mechanicalReduction>1</mechanicalReduction>
        </actuator>
    </transmission>
    <transmission name="trans_prbt_joint_3">
        <type>transmission_interface/SimpleTransmission</type>
        <joint name="prbt_joint_3">
            <hardwareInterface>hardware_interface/EffortJointInterface</hardwareInterface>
        </joint>
        <actuator name="prbt_joint_3_motor">
            <hardwareInterface>hardware_interface/EffortJointInterface</hardwareInterface>
            <mechanicalReduction>1</mechanicalReduction>
        </actuator>
    </transmission>
    <transmission name="trans_prbt_joint_4">
        <type>transmission_interface/SimpleTransmission</type>
        <joint name="prbt_joint_4">
            <hardwareInterface>hardware_interface/EffortJointInterface</hardwareInterface>
        </joint>
        <actuator name="prbt_joint_4_motor">
            <hardwareInterface>hardware_interface/EffortJointInterface</hardwareInterface>
            <mechanicalReduction>1</mechanicalReduction>
        </actuator>
    </transmission>
    <transmission name="trans_prbt_joint_5">
        <type>transmission_interface/SimpleTransmission</type>
        <joint name="prbt_joint_5">
            <hardwareInterface>hardware_interface/EffortJointInterface</hardwareInterface>
        </joint>
        <actuator name="prbt_joint_5_motor">
            <hardwareInterface>hardware_interface/EffortJointInterface</hardwareInterface>
            <mechanicalReduction>1</mechanicalReduction>
        </actuator>
    </transmission>
    <transmission name="trans_prbt_joint_6">
        <type>transmission_interface/SimpleTransmission</type>
        <joint name="prbt_joint_6">
            <hardwareInterface>hardware_interface/EffortJointInterface</hardwareInterface>
        </joint>
        <actuator name="prbt_joint_6_motor">
            <hardwareInterface>hardware_interface/EffortJointInterface</hardwareInterface>
            <mechanicalReduction>1</mechanicalReduction>
        </actuator>
    </transmission>
    <gazebo>
        <plugin name="gazebo_ros_control" filename="libgazebo_ros_control.so">
            <robotNamespace>/</robotNamespace>
        </plugin>
    </gazebo>
</robot>
